{
 "cells": [
  {
   "cell_type": "code",
   "execution_count": null,
   "id": "62bdd7c9",
   "metadata": {},
   "outputs": [],
   "source": [
    "# ===== 셀 1: 환경 및 모듈 import =====\n",
    "import sys\n",
    "sys.path.append('..')  # 상위 폴더(AI/)의 모듈 import 가능하게\n",
    "\n",
    "from dotenv import load_dotenv\n",
    "load_dotenv()\n",
    "\n",
    "# 우리가 만든 모듈 import\n",
    "from chains.classifier import classify_question\n",
    "from chains.rag_chain import query_rag\n",
    "from chains.general_chain import query_general_advice\n",
    "\n",
    "# ===== 셀 2: 질문 분류 → RAG 실행 통합 테스트 =====\n",
    "def test_full_pipeline(question: str):\n",
    "    \"\"\"전체 파이프라인 테스트\"\"\"\n",
    "    \n",
    "    print(f\"\\n{'='*70}\")\n",
    "    print(f\"질문: {question}\")\n",
    "    print('='*70)\n",
    "    \n",
    "    # 1. 질문 분류\n",
    "    category = classify_question(question)\n",
    "    print(f\"\\n[분류] {category}\")\n",
    "    \n",
    "    # 2. 카테고리별 처리\n",
    "    if category == \"analyst_report\":\n",
    "        result = query_rag(question, collection_name=\"test_reports\")\n",
    "        print(f\"\\n[답변]\\n{result['answer']}\")\n",
    "        print(f\"\\n[출처]\")\n",
    "        for src in result['sources']:\n",
    "            print(f\"  - {src}\")\n",
    "    \n",
    "    elif category == \"general\":\n",
    "        answer = query_general_advice(question)\n",
    "        print(f\"\\n[답변]\\n{answer}\")\n",
    "    \n",
    "    else:\n",
    "        print(f\"\\n[알림] {category} 카테고리는 아직 구현 중입니다.\")\n",
    "\n",
    "# ===== 셀 3: 여러 질문 테스트 =====\n",
    "test_questions = [\n",
    "    \"삼성전자 AI 반도체 전망은?\",\n",
    "    \"초보자한테 추천하는 투자 전략은?\",\n",
    "    \"네이버 목표주가는?\",\n",
    "    \"분산투자가 뭐야?\"\n",
    "]\n",
    "\n",
    "for q in test_questions:\n",
    "    test_full_pipeline(q)\n"
   ]
  },
  {
   "cell_type": "code",
   "execution_count": null,
   "id": "6427f9f2",
   "metadata": {},
   "outputs": [
    {
     "ename": "ConnectionError",
     "evalue": "HTTPConnectionPool(host='localhost', port=8001): Max retries exceeded with url: /api/ai/query (Caused by NewConnectionError('<urllib3.connection.HTTPConnection object at 0x000001DF40DE36A0>: Failed to establish a new connection: [WinError 10061] 대상 컴퓨터에서 연결을 거부했으므로 연결하지 못했습니다'))",
     "output_type": "error",
     "traceback": [
      "\u001b[1;31m---------------------------------------------------------------------------\u001b[0m",
      "\u001b[1;31mConnectionRefusedError\u001b[0m                    Traceback (most recent call last)",
      "File \u001b[1;32mc:\\Users\\user\\anaconda3\\envs\\myenv\\lib\\site-packages\\urllib3\\connection.py:198\u001b[0m, in \u001b[0;36mHTTPConnection._new_conn\u001b[1;34m(self)\u001b[0m\n\u001b[0;32m    197\u001b[0m \u001b[38;5;28;01mtry\u001b[39;00m:\n\u001b[1;32m--> 198\u001b[0m     sock \u001b[38;5;241m=\u001b[39m \u001b[43mconnection\u001b[49m\u001b[38;5;241;43m.\u001b[39;49m\u001b[43mcreate_connection\u001b[49m\u001b[43m(\u001b[49m\n\u001b[0;32m    199\u001b[0m \u001b[43m        \u001b[49m\u001b[43m(\u001b[49m\u001b[38;5;28;43mself\u001b[39;49m\u001b[38;5;241;43m.\u001b[39;49m\u001b[43m_dns_host\u001b[49m\u001b[43m,\u001b[49m\u001b[43m \u001b[49m\u001b[38;5;28;43mself\u001b[39;49m\u001b[38;5;241;43m.\u001b[39;49m\u001b[43mport\u001b[49m\u001b[43m)\u001b[49m\u001b[43m,\u001b[49m\n\u001b[0;32m    200\u001b[0m \u001b[43m        \u001b[49m\u001b[38;5;28;43mself\u001b[39;49m\u001b[38;5;241;43m.\u001b[39;49m\u001b[43mtimeout\u001b[49m\u001b[43m,\u001b[49m\n\u001b[0;32m    201\u001b[0m \u001b[43m        \u001b[49m\u001b[43msource_address\u001b[49m\u001b[38;5;241;43m=\u001b[39;49m\u001b[38;5;28;43mself\u001b[39;49m\u001b[38;5;241;43m.\u001b[39;49m\u001b[43msource_address\u001b[49m\u001b[43m,\u001b[49m\n\u001b[0;32m    202\u001b[0m \u001b[43m        \u001b[49m\u001b[43msocket_options\u001b[49m\u001b[38;5;241;43m=\u001b[39;49m\u001b[38;5;28;43mself\u001b[39;49m\u001b[38;5;241;43m.\u001b[39;49m\u001b[43msocket_options\u001b[49m\u001b[43m,\u001b[49m\n\u001b[0;32m    203\u001b[0m \u001b[43m    \u001b[49m\u001b[43m)\u001b[49m\n\u001b[0;32m    204\u001b[0m \u001b[38;5;28;01mexcept\u001b[39;00m socket\u001b[38;5;241m.\u001b[39mgaierror \u001b[38;5;28;01mas\u001b[39;00m e:\n",
      "File \u001b[1;32mc:\\Users\\user\\anaconda3\\envs\\myenv\\lib\\site-packages\\urllib3\\util\\connection.py:85\u001b[0m, in \u001b[0;36mcreate_connection\u001b[1;34m(address, timeout, source_address, socket_options)\u001b[0m\n\u001b[0;32m     84\u001b[0m \u001b[38;5;28;01mtry\u001b[39;00m:\n\u001b[1;32m---> 85\u001b[0m     \u001b[38;5;28;01mraise\u001b[39;00m err\n\u001b[0;32m     86\u001b[0m \u001b[38;5;28;01mfinally\u001b[39;00m:\n\u001b[0;32m     87\u001b[0m     \u001b[38;5;66;03m# Break explicitly a reference cycle\u001b[39;00m\n",
      "File \u001b[1;32mc:\\Users\\user\\anaconda3\\envs\\myenv\\lib\\site-packages\\urllib3\\util\\connection.py:73\u001b[0m, in \u001b[0;36mcreate_connection\u001b[1;34m(address, timeout, source_address, socket_options)\u001b[0m\n\u001b[0;32m     72\u001b[0m     sock\u001b[38;5;241m.\u001b[39mbind(source_address)\n\u001b[1;32m---> 73\u001b[0m \u001b[43msock\u001b[49m\u001b[38;5;241;43m.\u001b[39;49m\u001b[43mconnect\u001b[49m\u001b[43m(\u001b[49m\u001b[43msa\u001b[49m\u001b[43m)\u001b[49m\n\u001b[0;32m     74\u001b[0m \u001b[38;5;66;03m# Break explicitly a reference cycle\u001b[39;00m\n",
      "\u001b[1;31mConnectionRefusedError\u001b[0m: [WinError 10061] 대상 컴퓨터에서 연결을 거부했으므로 연결하지 못했습니다",
      "\nThe above exception was the direct cause of the following exception:\n",
      "\u001b[1;31mNewConnectionError\u001b[0m                        Traceback (most recent call last)",
      "File \u001b[1;32mc:\\Users\\user\\anaconda3\\envs\\myenv\\lib\\site-packages\\urllib3\\connectionpool.py:787\u001b[0m, in \u001b[0;36mHTTPConnectionPool.urlopen\u001b[1;34m(self, method, url, body, headers, retries, redirect, assert_same_host, timeout, pool_timeout, release_conn, chunked, body_pos, preload_content, decode_content, **response_kw)\u001b[0m\n\u001b[0;32m    786\u001b[0m \u001b[38;5;66;03m# Make the request on the HTTPConnection object\u001b[39;00m\n\u001b[1;32m--> 787\u001b[0m response \u001b[38;5;241m=\u001b[39m \u001b[38;5;28mself\u001b[39m\u001b[38;5;241m.\u001b[39m_make_request(\n\u001b[0;32m    788\u001b[0m     conn,\n\u001b[0;32m    789\u001b[0m     method,\n\u001b[0;32m    790\u001b[0m     url,\n\u001b[0;32m    791\u001b[0m     timeout\u001b[38;5;241m=\u001b[39mtimeout_obj,\n\u001b[0;32m    792\u001b[0m     body\u001b[38;5;241m=\u001b[39mbody,\n\u001b[0;32m    793\u001b[0m     headers\u001b[38;5;241m=\u001b[39mheaders,\n\u001b[0;32m    794\u001b[0m     chunked\u001b[38;5;241m=\u001b[39mchunked,\n\u001b[0;32m    795\u001b[0m     retries\u001b[38;5;241m=\u001b[39mretries,\n\u001b[0;32m    796\u001b[0m     response_conn\u001b[38;5;241m=\u001b[39mresponse_conn,\n\u001b[0;32m    797\u001b[0m     preload_content\u001b[38;5;241m=\u001b[39mpreload_content,\n\u001b[0;32m    798\u001b[0m     decode_content\u001b[38;5;241m=\u001b[39mdecode_content,\n\u001b[0;32m    799\u001b[0m     \u001b[38;5;241m*\u001b[39m\u001b[38;5;241m*\u001b[39mresponse_kw,\n\u001b[0;32m    800\u001b[0m )\n\u001b[0;32m    802\u001b[0m \u001b[38;5;66;03m# Everything went great!\u001b[39;00m\n",
      "File \u001b[1;32mc:\\Users\\user\\anaconda3\\envs\\myenv\\lib\\site-packages\\urllib3\\connectionpool.py:493\u001b[0m, in \u001b[0;36mHTTPConnectionPool._make_request\u001b[1;34m(self, conn, method, url, body, headers, retries, timeout, chunked, response_conn, preload_content, decode_content, enforce_content_length)\u001b[0m\n\u001b[0;32m    492\u001b[0m \u001b[38;5;28;01mtry\u001b[39;00m:\n\u001b[1;32m--> 493\u001b[0m     \u001b[43mconn\u001b[49m\u001b[38;5;241;43m.\u001b[39;49m\u001b[43mrequest\u001b[49m\u001b[43m(\u001b[49m\n\u001b[0;32m    494\u001b[0m \u001b[43m        \u001b[49m\u001b[43mmethod\u001b[49m\u001b[43m,\u001b[49m\n\u001b[0;32m    495\u001b[0m \u001b[43m        \u001b[49m\u001b[43murl\u001b[49m\u001b[43m,\u001b[49m\n\u001b[0;32m    496\u001b[0m \u001b[43m        \u001b[49m\u001b[43mbody\u001b[49m\u001b[38;5;241;43m=\u001b[39;49m\u001b[43mbody\u001b[49m\u001b[43m,\u001b[49m\n\u001b[0;32m    497\u001b[0m \u001b[43m        \u001b[49m\u001b[43mheaders\u001b[49m\u001b[38;5;241;43m=\u001b[39;49m\u001b[43mheaders\u001b[49m\u001b[43m,\u001b[49m\n\u001b[0;32m    498\u001b[0m \u001b[43m        \u001b[49m\u001b[43mchunked\u001b[49m\u001b[38;5;241;43m=\u001b[39;49m\u001b[43mchunked\u001b[49m\u001b[43m,\u001b[49m\n\u001b[0;32m    499\u001b[0m \u001b[43m        \u001b[49m\u001b[43mpreload_content\u001b[49m\u001b[38;5;241;43m=\u001b[39;49m\u001b[43mpreload_content\u001b[49m\u001b[43m,\u001b[49m\n\u001b[0;32m    500\u001b[0m \u001b[43m        \u001b[49m\u001b[43mdecode_content\u001b[49m\u001b[38;5;241;43m=\u001b[39;49m\u001b[43mdecode_content\u001b[49m\u001b[43m,\u001b[49m\n\u001b[0;32m    501\u001b[0m \u001b[43m        \u001b[49m\u001b[43menforce_content_length\u001b[49m\u001b[38;5;241;43m=\u001b[39;49m\u001b[43menforce_content_length\u001b[49m\u001b[43m,\u001b[49m\n\u001b[0;32m    502\u001b[0m \u001b[43m    \u001b[49m\u001b[43m)\u001b[49m\n\u001b[0;32m    504\u001b[0m \u001b[38;5;66;03m# We are swallowing BrokenPipeError (errno.EPIPE) since the server is\u001b[39;00m\n\u001b[0;32m    505\u001b[0m \u001b[38;5;66;03m# legitimately able to close the connection after sending a valid response.\u001b[39;00m\n\u001b[0;32m    506\u001b[0m \u001b[38;5;66;03m# With this behaviour, the received response is still readable.\u001b[39;00m\n",
      "File \u001b[1;32mc:\\Users\\user\\anaconda3\\envs\\myenv\\lib\\site-packages\\urllib3\\connection.py:494\u001b[0m, in \u001b[0;36mHTTPConnection.request\u001b[1;34m(self, method, url, body, headers, chunked, preload_content, decode_content, enforce_content_length)\u001b[0m\n\u001b[0;32m    493\u001b[0m     \u001b[38;5;28mself\u001b[39m\u001b[38;5;241m.\u001b[39mputheader(header, value)\n\u001b[1;32m--> 494\u001b[0m \u001b[38;5;28;43mself\u001b[39;49m\u001b[38;5;241;43m.\u001b[39;49m\u001b[43mendheaders\u001b[49m\u001b[43m(\u001b[49m\u001b[43m)\u001b[49m\n\u001b[0;32m    496\u001b[0m \u001b[38;5;66;03m# If we're given a body we start sending that in chunks.\u001b[39;00m\n",
      "File \u001b[1;32mc:\\Users\\user\\anaconda3\\envs\\myenv\\lib\\http\\client.py:1280\u001b[0m, in \u001b[0;36mHTTPConnection.endheaders\u001b[1;34m(self, message_body, encode_chunked)\u001b[0m\n\u001b[0;32m   1279\u001b[0m     \u001b[38;5;28;01mraise\u001b[39;00m CannotSendHeader()\n\u001b[1;32m-> 1280\u001b[0m \u001b[38;5;28;43mself\u001b[39;49m\u001b[38;5;241;43m.\u001b[39;49m\u001b[43m_send_output\u001b[49m\u001b[43m(\u001b[49m\u001b[43mmessage_body\u001b[49m\u001b[43m,\u001b[49m\u001b[43m \u001b[49m\u001b[43mencode_chunked\u001b[49m\u001b[38;5;241;43m=\u001b[39;49m\u001b[43mencode_chunked\u001b[49m\u001b[43m)\u001b[49m\n",
      "File \u001b[1;32mc:\\Users\\user\\anaconda3\\envs\\myenv\\lib\\http\\client.py:1040\u001b[0m, in \u001b[0;36mHTTPConnection._send_output\u001b[1;34m(self, message_body, encode_chunked)\u001b[0m\n\u001b[0;32m   1039\u001b[0m \u001b[38;5;28;01mdel\u001b[39;00m \u001b[38;5;28mself\u001b[39m\u001b[38;5;241m.\u001b[39m_buffer[:]\n\u001b[1;32m-> 1040\u001b[0m \u001b[38;5;28;43mself\u001b[39;49m\u001b[38;5;241;43m.\u001b[39;49m\u001b[43msend\u001b[49m\u001b[43m(\u001b[49m\u001b[43mmsg\u001b[49m\u001b[43m)\u001b[49m\n\u001b[0;32m   1042\u001b[0m \u001b[38;5;28;01mif\u001b[39;00m message_body \u001b[38;5;129;01mis\u001b[39;00m \u001b[38;5;129;01mnot\u001b[39;00m \u001b[38;5;28;01mNone\u001b[39;00m:\n\u001b[0;32m   1043\u001b[0m \n\u001b[0;32m   1044\u001b[0m     \u001b[38;5;66;03m# create a consistent interface to message_body\u001b[39;00m\n",
      "File \u001b[1;32mc:\\Users\\user\\anaconda3\\envs\\myenv\\lib\\http\\client.py:980\u001b[0m, in \u001b[0;36mHTTPConnection.send\u001b[1;34m(self, data)\u001b[0m\n\u001b[0;32m    979\u001b[0m \u001b[38;5;28;01mif\u001b[39;00m \u001b[38;5;28mself\u001b[39m\u001b[38;5;241m.\u001b[39mauto_open:\n\u001b[1;32m--> 980\u001b[0m     \u001b[38;5;28;43mself\u001b[39;49m\u001b[38;5;241;43m.\u001b[39;49m\u001b[43mconnect\u001b[49m\u001b[43m(\u001b[49m\u001b[43m)\u001b[49m\n\u001b[0;32m    981\u001b[0m \u001b[38;5;28;01melse\u001b[39;00m:\n",
      "File \u001b[1;32mc:\\Users\\user\\anaconda3\\envs\\myenv\\lib\\site-packages\\urllib3\\connection.py:325\u001b[0m, in \u001b[0;36mHTTPConnection.connect\u001b[1;34m(self)\u001b[0m\n\u001b[0;32m    324\u001b[0m \u001b[38;5;28;01mdef\u001b[39;00m\u001b[38;5;250m \u001b[39m\u001b[38;5;21mconnect\u001b[39m(\u001b[38;5;28mself\u001b[39m) \u001b[38;5;241m-\u001b[39m\u001b[38;5;241m>\u001b[39m \u001b[38;5;28;01mNone\u001b[39;00m:\n\u001b[1;32m--> 325\u001b[0m     \u001b[38;5;28mself\u001b[39m\u001b[38;5;241m.\u001b[39msock \u001b[38;5;241m=\u001b[39m \u001b[38;5;28;43mself\u001b[39;49m\u001b[38;5;241;43m.\u001b[39;49m\u001b[43m_new_conn\u001b[49m\u001b[43m(\u001b[49m\u001b[43m)\u001b[49m\n\u001b[0;32m    326\u001b[0m     \u001b[38;5;28;01mif\u001b[39;00m \u001b[38;5;28mself\u001b[39m\u001b[38;5;241m.\u001b[39m_tunnel_host:\n\u001b[0;32m    327\u001b[0m         \u001b[38;5;66;03m# If we're tunneling it means we're connected to our proxy.\u001b[39;00m\n",
      "File \u001b[1;32mc:\\Users\\user\\anaconda3\\envs\\myenv\\lib\\site-packages\\urllib3\\connection.py:213\u001b[0m, in \u001b[0;36mHTTPConnection._new_conn\u001b[1;34m(self)\u001b[0m\n\u001b[0;32m    212\u001b[0m \u001b[38;5;28;01mexcept\u001b[39;00m \u001b[38;5;167;01mOSError\u001b[39;00m \u001b[38;5;28;01mas\u001b[39;00m e:\n\u001b[1;32m--> 213\u001b[0m     \u001b[38;5;28;01mraise\u001b[39;00m NewConnectionError(\n\u001b[0;32m    214\u001b[0m         \u001b[38;5;28mself\u001b[39m, \u001b[38;5;124mf\u001b[39m\u001b[38;5;124m\"\u001b[39m\u001b[38;5;124mFailed to establish a new connection: \u001b[39m\u001b[38;5;132;01m{\u001b[39;00me\u001b[38;5;132;01m}\u001b[39;00m\u001b[38;5;124m\"\u001b[39m\n\u001b[0;32m    215\u001b[0m     ) \u001b[38;5;28;01mfrom\u001b[39;00m\u001b[38;5;250m \u001b[39m\u001b[38;5;21;01me\u001b[39;00m\n\u001b[0;32m    217\u001b[0m sys\u001b[38;5;241m.\u001b[39maudit(\u001b[38;5;124m\"\u001b[39m\u001b[38;5;124mhttp.client.connect\u001b[39m\u001b[38;5;124m\"\u001b[39m, \u001b[38;5;28mself\u001b[39m, \u001b[38;5;28mself\u001b[39m\u001b[38;5;241m.\u001b[39mhost, \u001b[38;5;28mself\u001b[39m\u001b[38;5;241m.\u001b[39mport)\n",
      "\u001b[1;31mNewConnectionError\u001b[0m: <urllib3.connection.HTTPConnection object at 0x000001DF40DE36A0>: Failed to establish a new connection: [WinError 10061] 대상 컴퓨터에서 연결을 거부했으므로 연결하지 못했습니다",
      "\nThe above exception was the direct cause of the following exception:\n",
      "\u001b[1;31mMaxRetryError\u001b[0m                             Traceback (most recent call last)",
      "File \u001b[1;32mc:\\Users\\user\\anaconda3\\envs\\myenv\\lib\\site-packages\\requests\\adapters.py:644\u001b[0m, in \u001b[0;36mHTTPAdapter.send\u001b[1;34m(self, request, stream, timeout, verify, cert, proxies)\u001b[0m\n\u001b[0;32m    643\u001b[0m \u001b[38;5;28;01mtry\u001b[39;00m:\n\u001b[1;32m--> 644\u001b[0m     resp \u001b[38;5;241m=\u001b[39m \u001b[43mconn\u001b[49m\u001b[38;5;241;43m.\u001b[39;49m\u001b[43murlopen\u001b[49m\u001b[43m(\u001b[49m\n\u001b[0;32m    645\u001b[0m \u001b[43m        \u001b[49m\u001b[43mmethod\u001b[49m\u001b[38;5;241;43m=\u001b[39;49m\u001b[43mrequest\u001b[49m\u001b[38;5;241;43m.\u001b[39;49m\u001b[43mmethod\u001b[49m\u001b[43m,\u001b[49m\n\u001b[0;32m    646\u001b[0m \u001b[43m        \u001b[49m\u001b[43murl\u001b[49m\u001b[38;5;241;43m=\u001b[39;49m\u001b[43murl\u001b[49m\u001b[43m,\u001b[49m\n\u001b[0;32m    647\u001b[0m \u001b[43m        \u001b[49m\u001b[43mbody\u001b[49m\u001b[38;5;241;43m=\u001b[39;49m\u001b[43mrequest\u001b[49m\u001b[38;5;241;43m.\u001b[39;49m\u001b[43mbody\u001b[49m\u001b[43m,\u001b[49m\n\u001b[0;32m    648\u001b[0m \u001b[43m        \u001b[49m\u001b[43mheaders\u001b[49m\u001b[38;5;241;43m=\u001b[39;49m\u001b[43mrequest\u001b[49m\u001b[38;5;241;43m.\u001b[39;49m\u001b[43mheaders\u001b[49m\u001b[43m,\u001b[49m\n\u001b[0;32m    649\u001b[0m \u001b[43m        \u001b[49m\u001b[43mredirect\u001b[49m\u001b[38;5;241;43m=\u001b[39;49m\u001b[38;5;28;43;01mFalse\u001b[39;49;00m\u001b[43m,\u001b[49m\n\u001b[0;32m    650\u001b[0m \u001b[43m        \u001b[49m\u001b[43massert_same_host\u001b[49m\u001b[38;5;241;43m=\u001b[39;49m\u001b[38;5;28;43;01mFalse\u001b[39;49;00m\u001b[43m,\u001b[49m\n\u001b[0;32m    651\u001b[0m \u001b[43m        \u001b[49m\u001b[43mpreload_content\u001b[49m\u001b[38;5;241;43m=\u001b[39;49m\u001b[38;5;28;43;01mFalse\u001b[39;49;00m\u001b[43m,\u001b[49m\n\u001b[0;32m    652\u001b[0m \u001b[43m        \u001b[49m\u001b[43mdecode_content\u001b[49m\u001b[38;5;241;43m=\u001b[39;49m\u001b[38;5;28;43;01mFalse\u001b[39;49;00m\u001b[43m,\u001b[49m\n\u001b[0;32m    653\u001b[0m \u001b[43m        \u001b[49m\u001b[43mretries\u001b[49m\u001b[38;5;241;43m=\u001b[39;49m\u001b[38;5;28;43mself\u001b[39;49m\u001b[38;5;241;43m.\u001b[39;49m\u001b[43mmax_retries\u001b[49m\u001b[43m,\u001b[49m\n\u001b[0;32m    654\u001b[0m \u001b[43m        \u001b[49m\u001b[43mtimeout\u001b[49m\u001b[38;5;241;43m=\u001b[39;49m\u001b[43mtimeout\u001b[49m\u001b[43m,\u001b[49m\n\u001b[0;32m    655\u001b[0m \u001b[43m        \u001b[49m\u001b[43mchunked\u001b[49m\u001b[38;5;241;43m=\u001b[39;49m\u001b[43mchunked\u001b[49m\u001b[43m,\u001b[49m\n\u001b[0;32m    656\u001b[0m \u001b[43m    \u001b[49m\u001b[43m)\u001b[49m\n\u001b[0;32m    658\u001b[0m \u001b[38;5;28;01mexcept\u001b[39;00m (ProtocolError, \u001b[38;5;167;01mOSError\u001b[39;00m) \u001b[38;5;28;01mas\u001b[39;00m err:\n",
      "File \u001b[1;32mc:\\Users\\user\\anaconda3\\envs\\myenv\\lib\\site-packages\\urllib3\\connectionpool.py:841\u001b[0m, in \u001b[0;36mHTTPConnectionPool.urlopen\u001b[1;34m(self, method, url, body, headers, retries, redirect, assert_same_host, timeout, pool_timeout, release_conn, chunked, body_pos, preload_content, decode_content, **response_kw)\u001b[0m\n\u001b[0;32m    839\u001b[0m     new_e \u001b[38;5;241m=\u001b[39m ProtocolError(\u001b[38;5;124m\"\u001b[39m\u001b[38;5;124mConnection aborted.\u001b[39m\u001b[38;5;124m\"\u001b[39m, new_e)\n\u001b[1;32m--> 841\u001b[0m retries \u001b[38;5;241m=\u001b[39m \u001b[43mretries\u001b[49m\u001b[38;5;241;43m.\u001b[39;49m\u001b[43mincrement\u001b[49m\u001b[43m(\u001b[49m\n\u001b[0;32m    842\u001b[0m \u001b[43m    \u001b[49m\u001b[43mmethod\u001b[49m\u001b[43m,\u001b[49m\u001b[43m \u001b[49m\u001b[43murl\u001b[49m\u001b[43m,\u001b[49m\u001b[43m \u001b[49m\u001b[43merror\u001b[49m\u001b[38;5;241;43m=\u001b[39;49m\u001b[43mnew_e\u001b[49m\u001b[43m,\u001b[49m\u001b[43m \u001b[49m\u001b[43m_pool\u001b[49m\u001b[38;5;241;43m=\u001b[39;49m\u001b[38;5;28;43mself\u001b[39;49m\u001b[43m,\u001b[49m\u001b[43m \u001b[49m\u001b[43m_stacktrace\u001b[49m\u001b[38;5;241;43m=\u001b[39;49m\u001b[43msys\u001b[49m\u001b[38;5;241;43m.\u001b[39;49m\u001b[43mexc_info\u001b[49m\u001b[43m(\u001b[49m\u001b[43m)\u001b[49m\u001b[43m[\u001b[49m\u001b[38;5;241;43m2\u001b[39;49m\u001b[43m]\u001b[49m\n\u001b[0;32m    843\u001b[0m \u001b[43m\u001b[49m\u001b[43m)\u001b[49m\n\u001b[0;32m    844\u001b[0m retries\u001b[38;5;241m.\u001b[39msleep()\n",
      "File \u001b[1;32mc:\\Users\\user\\anaconda3\\envs\\myenv\\lib\\site-packages\\urllib3\\util\\retry.py:519\u001b[0m, in \u001b[0;36mRetry.increment\u001b[1;34m(self, method, url, response, error, _pool, _stacktrace)\u001b[0m\n\u001b[0;32m    518\u001b[0m     reason \u001b[38;5;241m=\u001b[39m error \u001b[38;5;129;01mor\u001b[39;00m ResponseError(cause)\n\u001b[1;32m--> 519\u001b[0m     \u001b[38;5;28;01mraise\u001b[39;00m MaxRetryError(_pool, url, reason) \u001b[38;5;28;01mfrom\u001b[39;00m\u001b[38;5;250m \u001b[39m\u001b[38;5;21;01mreason\u001b[39;00m  \u001b[38;5;66;03m# type: ignore[arg-type]\u001b[39;00m\n\u001b[0;32m    521\u001b[0m log\u001b[38;5;241m.\u001b[39mdebug(\u001b[38;5;124m\"\u001b[39m\u001b[38;5;124mIncremented Retry for (url=\u001b[39m\u001b[38;5;124m'\u001b[39m\u001b[38;5;132;01m%s\u001b[39;00m\u001b[38;5;124m'\u001b[39m\u001b[38;5;124m): \u001b[39m\u001b[38;5;132;01m%r\u001b[39;00m\u001b[38;5;124m\"\u001b[39m, url, new_retry)\n",
      "\u001b[1;31mMaxRetryError\u001b[0m: HTTPConnectionPool(host='localhost', port=8001): Max retries exceeded with url: /api/ai/query (Caused by NewConnectionError('<urllib3.connection.HTTPConnection object at 0x000001DF40DE36A0>: Failed to establish a new connection: [WinError 10061] 대상 컴퓨터에서 연결을 거부했으므로 연결하지 못했습니다'))",
      "\nDuring handling of the above exception, another exception occurred:\n",
      "\u001b[1;31mConnectionError\u001b[0m                           Traceback (most recent call last)",
      "Cell \u001b[1;32mIn[1], line 9\u001b[0m\n\u001b[0;32m      3\u001b[0m url \u001b[38;5;241m=\u001b[39m \u001b[38;5;124m\"\u001b[39m\u001b[38;5;124mhttp://localhost:8001/api/ai/query\u001b[39m\u001b[38;5;124m\"\u001b[39m\n\u001b[0;32m      4\u001b[0m payload \u001b[38;5;241m=\u001b[39m {\n\u001b[0;32m      5\u001b[0m     \u001b[38;5;124m\"\u001b[39m\u001b[38;5;124msession_id\u001b[39m\u001b[38;5;124m\"\u001b[39m: \u001b[38;5;124m\"\u001b[39m\u001b[38;5;124mnb_test_01\u001b[39m\u001b[38;5;124m\"\u001b[39m,\n\u001b[0;32m      6\u001b[0m     \u001b[38;5;124m\"\u001b[39m\u001b[38;5;124mquestion\u001b[39m\u001b[38;5;124m\"\u001b[39m: \u001b[38;5;124m\"\u001b[39m\u001b[38;5;124m삼성전자 투자에 대한 긍정/부정 의견 분석해줘\u001b[39m\u001b[38;5;124m\"\u001b[39m\n\u001b[0;32m      7\u001b[0m }\n\u001b[1;32m----> 9\u001b[0m resp \u001b[38;5;241m=\u001b[39m \u001b[43mrequests\u001b[49m\u001b[38;5;241;43m.\u001b[39;49m\u001b[43mpost\u001b[49m\u001b[43m(\u001b[49m\u001b[43murl\u001b[49m\u001b[43m,\u001b[49m\u001b[43m \u001b[49m\u001b[43mjson\u001b[49m\u001b[38;5;241;43m=\u001b[39;49m\u001b[43mpayload\u001b[49m\u001b[43m)\u001b[49m\n\u001b[0;32m     10\u001b[0m data \u001b[38;5;241m=\u001b[39m resp\u001b[38;5;241m.\u001b[39mjson()\n\u001b[0;32m     12\u001b[0m \u001b[38;5;28mprint\u001b[39m(\u001b[38;5;124m\"\u001b[39m\u001b[38;5;124m💬 답변:\u001b[39m\u001b[38;5;124m\"\u001b[39m, data[\u001b[38;5;124m\"\u001b[39m\u001b[38;5;124manswer\u001b[39m\u001b[38;5;124m\"\u001b[39m])\n",
      "File \u001b[1;32mc:\\Users\\user\\anaconda3\\envs\\myenv\\lib\\site-packages\\requests\\api.py:115\u001b[0m, in \u001b[0;36mpost\u001b[1;34m(url, data, json, **kwargs)\u001b[0m\n\u001b[0;32m    103\u001b[0m \u001b[38;5;28;01mdef\u001b[39;00m\u001b[38;5;250m \u001b[39m\u001b[38;5;21mpost\u001b[39m(url, data\u001b[38;5;241m=\u001b[39m\u001b[38;5;28;01mNone\u001b[39;00m, json\u001b[38;5;241m=\u001b[39m\u001b[38;5;28;01mNone\u001b[39;00m, \u001b[38;5;241m*\u001b[39m\u001b[38;5;241m*\u001b[39mkwargs):\n\u001b[0;32m    104\u001b[0m \u001b[38;5;250m    \u001b[39m\u001b[38;5;124mr\u001b[39m\u001b[38;5;124;03m\"\"\"Sends a POST request.\u001b[39;00m\n\u001b[0;32m    105\u001b[0m \n\u001b[0;32m    106\u001b[0m \u001b[38;5;124;03m    :param url: URL for the new :class:`Request` object.\u001b[39;00m\n\u001b[1;32m   (...)\u001b[0m\n\u001b[0;32m    112\u001b[0m \u001b[38;5;124;03m    :rtype: requests.Response\u001b[39;00m\n\u001b[0;32m    113\u001b[0m \u001b[38;5;124;03m    \"\"\"\u001b[39;00m\n\u001b[1;32m--> 115\u001b[0m     \u001b[38;5;28;01mreturn\u001b[39;00m request(\u001b[38;5;124m\"\u001b[39m\u001b[38;5;124mpost\u001b[39m\u001b[38;5;124m\"\u001b[39m, url, data\u001b[38;5;241m=\u001b[39mdata, json\u001b[38;5;241m=\u001b[39mjson, \u001b[38;5;241m*\u001b[39m\u001b[38;5;241m*\u001b[39mkwargs)\n",
      "File \u001b[1;32mc:\\Users\\user\\anaconda3\\envs\\myenv\\lib\\site-packages\\requests\\api.py:59\u001b[0m, in \u001b[0;36mrequest\u001b[1;34m(method, url, **kwargs)\u001b[0m\n\u001b[0;32m     55\u001b[0m \u001b[38;5;66;03m# By using the 'with' statement we are sure the session is closed, thus we\u001b[39;00m\n\u001b[0;32m     56\u001b[0m \u001b[38;5;66;03m# avoid leaving sockets open which can trigger a ResourceWarning in some\u001b[39;00m\n\u001b[0;32m     57\u001b[0m \u001b[38;5;66;03m# cases, and look like a memory leak in others.\u001b[39;00m\n\u001b[0;32m     58\u001b[0m \u001b[38;5;28;01mwith\u001b[39;00m sessions\u001b[38;5;241m.\u001b[39mSession() \u001b[38;5;28;01mas\u001b[39;00m session:\n\u001b[1;32m---> 59\u001b[0m     \u001b[38;5;28;01mreturn\u001b[39;00m session\u001b[38;5;241m.\u001b[39mrequest(method\u001b[38;5;241m=\u001b[39mmethod, url\u001b[38;5;241m=\u001b[39murl, \u001b[38;5;241m*\u001b[39m\u001b[38;5;241m*\u001b[39mkwargs)\n",
      "File \u001b[1;32mc:\\Users\\user\\anaconda3\\envs\\myenv\\lib\\site-packages\\requests\\sessions.py:589\u001b[0m, in \u001b[0;36mSession.request\u001b[1;34m(self, method, url, params, data, headers, cookies, files, auth, timeout, allow_redirects, proxies, hooks, stream, verify, cert, json)\u001b[0m\n\u001b[0;32m    584\u001b[0m send_kwargs \u001b[38;5;241m=\u001b[39m {\n\u001b[0;32m    585\u001b[0m     \u001b[38;5;124m\"\u001b[39m\u001b[38;5;124mtimeout\u001b[39m\u001b[38;5;124m\"\u001b[39m: timeout,\n\u001b[0;32m    586\u001b[0m     \u001b[38;5;124m\"\u001b[39m\u001b[38;5;124mallow_redirects\u001b[39m\u001b[38;5;124m\"\u001b[39m: allow_redirects,\n\u001b[0;32m    587\u001b[0m }\n\u001b[0;32m    588\u001b[0m send_kwargs\u001b[38;5;241m.\u001b[39mupdate(settings)\n\u001b[1;32m--> 589\u001b[0m resp \u001b[38;5;241m=\u001b[39m \u001b[38;5;28mself\u001b[39m\u001b[38;5;241m.\u001b[39msend(prep, \u001b[38;5;241m*\u001b[39m\u001b[38;5;241m*\u001b[39msend_kwargs)\n\u001b[0;32m    591\u001b[0m \u001b[38;5;28;01mreturn\u001b[39;00m resp\n",
      "File \u001b[1;32mc:\\Users\\user\\anaconda3\\envs\\myenv\\lib\\site-packages\\requests\\sessions.py:703\u001b[0m, in \u001b[0;36mSession.send\u001b[1;34m(self, request, **kwargs)\u001b[0m\n\u001b[0;32m    700\u001b[0m start \u001b[38;5;241m=\u001b[39m preferred_clock()\n\u001b[0;32m    702\u001b[0m \u001b[38;5;66;03m# Send the request\u001b[39;00m\n\u001b[1;32m--> 703\u001b[0m r \u001b[38;5;241m=\u001b[39m adapter\u001b[38;5;241m.\u001b[39msend(request, \u001b[38;5;241m*\u001b[39m\u001b[38;5;241m*\u001b[39mkwargs)\n\u001b[0;32m    705\u001b[0m \u001b[38;5;66;03m# Total elapsed time of the request (approximately)\u001b[39;00m\n\u001b[0;32m    706\u001b[0m elapsed \u001b[38;5;241m=\u001b[39m preferred_clock() \u001b[38;5;241m-\u001b[39m start\n",
      "File \u001b[1;32mc:\\Users\\user\\anaconda3\\envs\\myenv\\lib\\site-packages\\requests\\adapters.py:677\u001b[0m, in \u001b[0;36mHTTPAdapter.send\u001b[1;34m(self, request, stream, timeout, verify, cert, proxies)\u001b[0m\n\u001b[0;32m    673\u001b[0m     \u001b[38;5;28;01mif\u001b[39;00m \u001b[38;5;28misinstance\u001b[39m(e\u001b[38;5;241m.\u001b[39mreason, _SSLError):\n\u001b[0;32m    674\u001b[0m         \u001b[38;5;66;03m# This branch is for urllib3 v1.22 and later.\u001b[39;00m\n\u001b[0;32m    675\u001b[0m         \u001b[38;5;28;01mraise\u001b[39;00m SSLError(e, request\u001b[38;5;241m=\u001b[39mrequest)\n\u001b[1;32m--> 677\u001b[0m     \u001b[38;5;28;01mraise\u001b[39;00m \u001b[38;5;167;01mConnectionError\u001b[39;00m(e, request\u001b[38;5;241m=\u001b[39mrequest)\n\u001b[0;32m    679\u001b[0m \u001b[38;5;28;01mexcept\u001b[39;00m ClosedPoolError \u001b[38;5;28;01mas\u001b[39;00m e:\n\u001b[0;32m    680\u001b[0m     \u001b[38;5;28;01mraise\u001b[39;00m \u001b[38;5;167;01mConnectionError\u001b[39;00m(e, request\u001b[38;5;241m=\u001b[39mrequest)\n",
      "\u001b[1;31mConnectionError\u001b[0m: HTTPConnectionPool(host='localhost', port=8001): Max retries exceeded with url: /api/ai/query (Caused by NewConnectionError('<urllib3.connection.HTTPConnection object at 0x000001DF40DE36A0>: Failed to establish a new connection: [WinError 10061] 대상 컴퓨터에서 연결을 거부했으므로 연결하지 못했습니다'))"
     ]
    }
   ],
   "source": []
  }
 ],
 "metadata": {
  "kernelspec": {
   "display_name": "myenv",
   "language": "python",
   "name": "python3"
  },
  "language_info": {
   "codemirror_mode": {
    "name": "ipython",
    "version": 3
   },
   "file_extension": ".py",
   "mimetype": "text/x-python",
   "name": "python",
   "nbconvert_exporter": "python",
   "pygments_lexer": "ipython3",
   "version": "3.9.24"
  }
 },
 "nbformat": 4,
 "nbformat_minor": 5
}
